Workbook

Sheet Guide
A1: How to use this inventory
A2: 1 | B2: Work through sources in this order: GitHub, Kaggle, Colab, LinkedIn, laptop, pendrives, mobile.
A3: 2 | B3: Add one row per project on the Projects sheet. Type in the blue cells; use the dropdowns where offered.
A4: 3 | B4: Tier: Featured = full case study (aim for 8 to 10). Standard = short card with summary and links. Archive = searchable list only.
A5: 4 | B5: Set Demo?, Docs? and Screenshot? honestly. Featured projects should have all three, so use these to see what is still missing.
A6: 5 | B6: Check the Summary sheet to see counts by technology, source and tier, and how many Featured slots are left.
A7: 5b | B7: Score each project 1 to 5 on the five yellow columns. The weighted score, rank and Featured candidate flag fill in automatically. Change weights on the Summary sheet.
A8: 5c | B8: Rule: keep at most 2 Featured projects per technology. This check is manual, so filter by Technology to review.
A9: 6 | B9: Row 5 on Projects is only an example. Overwrite or delete it. It is not counted in the Summary.
A10: Note | B10: The ID column fills itself once a title is entered. Do not type in it.

Sheet Projects
A1: Project inventory
A2: Fill the yellow-header columns for every project. Row 5 is an example: overwrite or delete it. Rows 6 to 305 feed the Summary sheet.
A4: ID | B4: Project title | C4: Year | D4: Source | E4: Technology | F4: Status | G4: Tier | H4: Link | I4: Demo? | J4: Docs? | K4: Screenshot? | L4: One-line note | M4: Complexity (1-5) | N4: Demo-ability (1-5) | O4: Relevance (1-5) | P4: Recency (1-5) | Q4: Docs ready (1-5) | R4: Weighted score | S4: Rank | T4: Suggestion
A5: P001 | B5: Prescription verification agent | C5: 2026 | D5: GitHub | E5: Agentic AI | F5: Done | G5: Featured | H5: https://github.com/Rajkumar-Ai-Engineer/PrescriptionAgent | I5: No | J5: Yes | K5: Yes | L5: Extracts and verifies prescriptions with human review | M5: 5 | N5: 4 | O5: 5 | P5: 5 | Q5: 4 | R5: =IF(COUNT(M5:Q5)<5,"",(M5*Summary!$F$5+N5*Summary!$F$6+O5*Summary!$F$7+P5*Summary!$F$8+Q5*Summary!$F$9)/Summary!$F$10) -> 4.6
A6: P002 | B6: Deep_agents_practice | C6: 2026 | D6: GitHub | E6: Agentic AI | F6: Done | G6: Archive | H6: https://github.com/Rajkumar-Ai-Engineer/deep_agents_practice | I6: No | J6: Yes | K6: Yes | L6: practice notebooks of all concept of deepagents | R6: =IF(COUNT(M6:Q6)<5,"",(M6*Summary!$F$5+N6*Summary!$F$6+O6*Summary!$F$7+P6*Summary!$F$8+Q6*Summary!$F$9)/Summary!$F$10) | S6: =IF(R6="","",RANK(R6,$R$6:$R$305)) | T6: =IF(S6="","",IF(S6<=Summary!$B$5,"Featured candidate",""))
A7: P003 | B7: E_mail_assistant_(deep_agents) | C7: 2026 | D7: GitHub | E7: Agentic AI | F7: Done | G7: Standard | H7: https://github.com/Rajkumar-Ai-Engineer/email_assistant_updated | I7: No | J7: Yes | K7: Yes | L7: DeepAgents based Email assiatnt with many subagents | R7: =IF(COUNT(M7:Q7)<5,"",(M7*Summary!$F$5+N7*Summary!$F$6+O7*Summary!$F$7+P7*Summary!$F$8+Q7*Summary!$F$9)/Summary!$F$10) | S7: =IF(R7="","",RANK(R7,$R$6:$R$305)) | T7: =IF(S7="","",IF(S7<=Summary!$B$5,"Featured candidate",""))
A8: P004 | B8: Sirax | C8: 2026 | D8: GitHub | E8: Gen AI | F8: Done | G8: Standard | H8: https://github.com/Rajkumar-Ai-Engineer/Sirex | I8: No | J8: Yes | K8: Yes | L8: Medical assistant chatbot | R8: =IF(COUNT(M8:Q8)<5,"",(M8*Summary!$F$5+N8*Summary!$F$6+O8*Summary!$F$7+P8*Summary!$F$8+Q8*Summary!$F$9)/Summary!$F$10) | S8: =IF(R8="","",RANK(R8,$R$6:$R$305)) | T8: =IF(S8="","",IF(S8<=Summary!$B$5,"Featured candidate",""))
A9: P005 | B9: BasicRagApplication | C9: 2026 | D9: GitHub | E9: Gen AI | F9: Done | G9: Archive | H9: https://github.com/Rajkumar-Ai-Engineer/BasicRagApplication | I9: No | J9: Yes | K9: Yes | L9: BasicRag application | R9: =IF(COUNT(M9:Q9)<5,"",(M9*Summary!$F$5+N9*Summary!$F$6+O9*Summary!$F$7+P9*Summary!$F$8+Q9*Summary!$F$9)/Summary!$F$10) | S9: =IF(R9="","",RANK(R9,$R$6:$R$305)) | T9: =IF(S9="","",IF(S9<=Summary!$B$5,"Featured candidate",""))
A10: P006 | B10: PokemonDataAnalysis | D10: GitHub | E10: Data Analytics | F10: Done | G10: Archive | H10: https://github.com/Rajkumar-Ai-Engineer/data_analytics/tree/main/POKEMON%20ANALYSIS | I10: No | J10: Yes | K10: Yes | L10: It consists notebooks where i performed data analysis using python | R10: =IF(COUNT(M10:Q10)<5,"",(M10*Summary!$F$5+N10*Summary!$F$6+O10*Summary!$F$7+P10*Summary!$F$8+Q10*Summary!$F$9)/Summary!$F$10) | S10: =IF(R10="","",RANK(R10,$R$6:$R$305)) | T10: =IF(S10="","",IF(S10<=Summary!$B$5,"Featured candidate",""))
A11: P007 | B11: FaceAttendanceSystem | D11: GitHub | E11: Computer Vision | F11: Done | G11: Archive | H11: https://github.com/Rajkumar-Ai-Engineer/FaceAttendanceSystem | I11: No | J11: Yes | K11: Yes | L11: Face Recognition Attendance System An automated, real-time face recognition attendance management system built with Python and OpenCV. The application detects and recognizes faces using computer vision to mark attendance with accurate timestamps, eliminating manual entry and proxy attendance. | R11: =IF(COUNT(M11:Q11)<5,"",(M11*Summary!$F$5+N11*Summary!$F$6+O11*Summary!$F$7+P11*Summary!$F$8+Q11*Summary!$F$9)/Summary!$F$10) | S11: =IF(R11="","",RANK(R11,$R$6:$R$305)) | T11: =IF(S11="","",IF(S11<=Summary!$B$5,"Featured candidate",""))
A12: P008 | B12: Animal-Img-Classification | D12: GitHub | E12: DL | F12: Done | G12: Archive | H12: https://github.com/Rajkumar-Ai-Engineer/Animal_img_classification/ | I12: No | J12: Yes | K12: Yes | L12: An end-to-end Computer Vision pipeline to download, preprocess, train, and test deep learning models for multi-class animal image classification. | R12: =IF(COUNT(M12:Q12)<5,"",(M12*Summary!$F$5+N12*Summary!$F$6+O12*Summary!$F$7+P12*Summary!$F$8+Q12*Summary!$F$9)/Summary!$F$10) | S12: =IF(R12="","",RANK(R12,$R$6:$R$305)) | T12: =IF(S12="","",IF(S12<=Summary!$B$5,"Featured candidate",""))
A13: P009 | B13: Player-face-recognition | D13: GitHub | E13: Computer Vision | F13: Done | G13: Archive | H13: https://github.com/Rajkumar-Ai-Engineer/player_face_recognition | I13: No | J13: Yes | K13: Yes | L13: An automated computer vision and deep learning pipeline designed to detect, encode, and identify sports players from video footage and images. | R13: =IF(COUNT(M13:Q13)<5,"",(M13*Summary!$F$5+N13*Summary!$F$6+O13*Summary!$F$7+P13*Summary!$F$8+Q13*Summary!$F$9)/Summary!$F$10) | S13: =IF(R13="","",RANK(R13,$R$6:$R$305)) | T13: =IF(S13="","",IF(S13<=Summary!$B$5,"Featured candidate",""))
A14: P010 | B14: Multi-Agent Streamlit App | D14: GitHub | E14: Gen AI | F14: Done | G14: Standard | H14: https://github.com/Rajkumar-Ai-Engineer/Agents | I14: No | J14: Yes | K14: Yes | L14: explains how to set up and run the Streamlit app with three agents (Swallow, React, and Deep Agent) with memory and MCP integration. | R14: =IF(COUNT(M14:Q14)<5,"",(M14*Summary!$F$5+N14*Summary!$F$6+O14*Summary!$F$7+P14*Summary!$F$8+Q14*Summary!$F$9)/Summary!$F$10) | S14: =IF(R14="","",RANK(R14,$R$6:$R$305)) | T14: =IF(S14="","",IF(S14<=Summary!$B$5,"Featured candidate",""))
A15: P011 | B15: AgenticRag | D15: GitHub | E15: Agentic AI | F15: Done | G15: Standard | H15: https://github.com/Rajkumar-Ai-Engineer/AgenticRag | I15: No | J15: Yes | K15: Yes | L15: An intelligent document retrieval and question-answering system that uses agentic workflows to decide when to retrieve documents and when to generate answers directly. | R15: =IF(COUNT(M15:Q15)<5,"",(M15*Summary!$F$5+N15*Summary!$F$6+O15*Summary!$F$7+P15*Summary!$F$8+Q15*Summary!$F$9)/Summary!$F$10) | S15: =IF(R15="","",RANK(R15,$R$6:$R$305)) | T15: =IF(S15="","",IF(S15<=Summary!$B$5,"Featured candidate",""))
A16: P012 | B16: VectorlessRag | D16: GitHub | E16: Gen AI | F16: Done | G16: Standard | H16: https://github.com/Rajkumar-Ai-Engineer/vectorless_rag | I16: No | J16: Yes | K16: Yes | L16: A RAG system that answers questions from documents without any vector embeddings or similarity search — instead it uses a LLM-navigated document tree built by PageIndex to find relevant sections. | R16: =IF(COUNT(M16:Q16)<5,"",(M16*Summary!$F$5+N16*Summary!$F$6+O16*Summary!$F$7+P16*Summary!$F$8+Q16*Summary!$F$9)/Summary!$F$10) | S16: =IF(R16="","",RANK(R16,$R$6:$R$305)) | T16: =IF(S16="","",IF(S16<=Summary!$B$5,"Featured candidate",""))
A17: P013 | B17: End-to-End RAG | D17: GitHub | E17: Gen AI | F17: Done | G17: Standard | H17: https://github.com/Rajkumar-Ai-Engineer/End_to_End_Rag | I17: No | J17: Yes | K17: Yes | L17: A production-ready Retrieval-Augmented Generation (RAG) application that lets you upload PDF documents and chat with them through a clean web UI — no JavaScript, fully server-rendered. | R17: =IF(COUNT(M17:Q17)<5,"",(M17*Summary!$F$5+N17*Summary!$F$6+O17*Summary!$F$7+P17*Summary!$F$8+Q17*Summary!$F$9)/Summary!$F$10) | S17: =IF(R17="","",RANK(R17,$R$6:$R$305)) | T17: =IF(S17="","",IF(S17<=Summary!$B$5,"Featured candidate",""))
A18: P014 | B18: fake_news_detection_v1 | D18: GitHub | E18: Gen AI | F18: Done | G18: Featured | H18: =IFERROR(__xludf.DUMMYFUNCTION("AI(""Fill an appropriate value for this cell based on the table context"")"),"https://github.com/Rajkumar-Ai-Engineer/fake_news_detection_v1") -> https://github.com/Rajkumar-Ai-Engineer/fake_news_detection_v1 | I18: No | J18: Yes | K18: Yes | L18: TruthGuard is an end-to-end multimodal fake news and misinformation detection platform. It processes diverse media formats—including video, audio, image, and raw text—using advanced transcription and OCR pipelines combined with Large Language Models via Groq to perform rapid fact verification and source analysis. | R18: =IF(COUNT(M18:Q18)<5,"",(M18*Summary!$F$5+N18*Summary!$F$6+O18*Summary!$F$7+P18*Summary!$F$8+Q18*Summary!$F$9)/Summary!$F$10) | S18: =IF(R18="","",RANK(R18,$R$6:$R$305)) | T18: =IF(S18="","",IF(S18<=Summary!$B$5,"Featured candidate",""))
A19: P015 | B19: MCP Agent Orchestration — Gmail + Google Calendar | D19: GitHub | E19: Gen AI | F19: Done | G19: Standard | H19: https://github.com/Rajkumar-Ai-Engineer/mcp-agent-orchestration | I19: No | J19: Yes | K19: Yes | L19: An AI-powered agent that uses Model Context Protocol (MCP) to orchestrate Gmail and Google Calendar tools via a Flask web interface. Powered by Groq's LLaMA 3.3 70B model with LangChain MCP adapters. | R19: =IF(COUNT(M19:Q19)<5,"",(M19*Summary!$F$5+N19*Summary!$F$6+O19*Summary!$F$7+P19*Summary!$F$8+Q19*Summary!$F$9)/Summary!$F$10) | S19: =IF(R19="","",RANK(R19,$R$6:$R$305)) | T19: =IF(S19="","",IF(S19<=Summary!$B$5,"Featured candidate",""))
A20: P016 | B20: Deepfake Detector — Audio + Video Fusion | D20: GitHub | E20: DL | F20: Done | G20: Standard | H20: https://github.com/Rajkumar-Ai-Engineer/deepfake-detector | I20: No | J20: Yes | K20: Yes | L20: A Deep Learning project that detects deepfake videos by fusing both video frame analysis and audio feature extraction into a single merged model. Uses Xception CNN for visual features and LSTM for temporal audio patterns. | R20: =IF(COUNT(M20:Q20)<5,"",(M20*Summary!$F$5+N20*Summary!$F$6+O20*Summary!$F$7+P20*Summary!$F$8+Q20*Summary!$F$9)/Summary!$F$10) | S20: =IF(R20="","",RANK(R20,$R$6:$R$305)) | T20: =IF(S20="","",IF(S20<=Summary!$B$5,"Featured candidate",""))
A21: P017 | B21: Tamil Literature Flowers — Full Stack Web App | D21: GitHub | E21: Gen AI | F21: Done | G21: Standard | H21: https://github.com/Rajkumar-Ai-Engineer/tamil-literature-flowers | I21: No | J21: Yes | K21: Yes | L21: A comprehensive full-stack web application showcasing 99 Kuruchi flowers from Tamil Sangam literature, organized by the traditional 5 Tinai (landscapes) with AI-powered information retrieval, user authentication, gamification, a chatbot, and real-time SMS/Telegram notifications. | R21: =IF(COUNT(M21:Q21)<5,"",(M21*Summary!$F$5+N21*Summary!$F$6+O21*Summary!$F$7+P21*Summary!$F$8+Q21*Summary!$F$9)/Summary!$F$10) | S21: =IF(R21="","",RANK(R21,$R$6:$R$305)) | T21: =IF(S21="","",IF(S21<=Summary!$B$5,"Featured candidate",""))
A22: P018 | B22: Tamil Flower Classifier | D22: GitHub | E22: DL | F22: Done | G22: Archive | H22: https://github.com/Rajkumar-Ai-Engineer/tamil-flower-classifier | I22: No | J22: Yes | K22: Yes | L22: A Deep Learning project that classifies Tamil Sangam literature flowers using EfficientNetV2 and GPT-4o Vision. Built to preserve and digitize Tamil botanical heritage by identifying flowers referenced in ancient Sangam poetry. | R22: =IF(COUNT(M22:Q22)<5,"",(M22*Summary!$F$5+N22*Summary!$F$6+O22*Summary!$F$7+P22*Summary!$F$8+Q22*Summary!$F$9)/Summary!$F$10) | S22: =IF(R22="","",RANK(R22,$R$6:$R$305)) | T22: =IF(S22="","",IF(S22<=Summary!$B$5,"Featured candidate",""))
A23: P019 | B23: Book Recommendation System | D23: GitHub | E23: ML | F23: Done | G23: Standard | H23: https://github.com/Rajkumar-Ai-Engineer/Book_recommentor_system | I23: No | J23: Yes | K23: Yes | L23: This is a production-grade book recommendation system that combines content-based and collaborative filtering into a hybrid model to overcome extreme data sparsity and cold-start issues. | R23: =IF(COUNT(M23:Q23)<5,"",(M23*Summary!$F$5+N23*Summary!$F$6+O23*Summary!$F$7+P23*Summary!$F$8+Q23*Summary!$F$9)/Summary!$F$10) | S23: =IF(R23="","",RANK(R23,$R$6:$R$305)) | T23: =IF(S23="","",IF(S23<=Summary!$B$5,"Featured candidate",""))
A24: P020 | B24: Smart Housing Assistant | D24: GitHub | E24: Gen AI | F24: Done | G24: Standard | H24: https://github.com/Rajkumar-Ai-Engineer/smart_housing_assistant | I24: No | J24: Yes | K24: Yes | L24: An AI-powered housing assistant that helps users evaluate real estate locations and estimate house construction costs using intelligent agents powered by Groq LLM and DuckDuckGo search. | R24: =IF(COUNT(M24:Q24)<5,"",(M24*Summary!$F$5+N24*Summary!$F$6+O24*Summary!$F$7+P24*Summary!$F$8+Q24*Summary!$F$9)/Summary!$F$10) | S24: =IF(R24="","",RANK(R24,$R$6:$R$305)) | T24: =IF(S24="","",IF(S24<=Summary!$B$5,"Featured candidate",""))
A25: P021 | B25: Holiday Trip Planner | D25: GitHub | E25: Agentic AI | F25: Done | G25: Featured | H25: https://github.com/Rajkumar-Ai-Engineer/HolidayPlanner | I25: No | J25: Yes | K25: Yes | L25: AI-powered holiday trip planning application using multi-agent system with FastAPI backend. | R25: =IF(COUNT(M25:Q25)<5,"",(M25*Summary!$F$5+N25*Summary!$F$6+O25*Summary!$F$7+P25*Summary!$F$8+Q25*Summary!$F$9)/Summary!$F$10) | S25: =IF(R25="","",RANK(R25,$R$6:$R$305)) | T25: =IF(S25="","",IF(S25<=Summary!$B$5,"Featured candidate",""))
A26: P022 | B26: URLSummarizer | D26: GitHub | E26: Gen AI | F26: Done | G26: Archive | H26: https://github.com/Rajkumar-Ai-Engineer/URLSummarizer | I26: No | J26: Yes | K26: Yes | L26: An AI-powered web tool built in Python that takes any webpage or article URL, extracts its main content, and produces concise, structured summaries using Large Language Models (LLMs). | R26: =IF(COUNT(M26:Q26)<5,"",(M26*Summary!$F$5+N26*Summary!$F$6+O26*Summary!$F$7+P26*Summary!$F$8+Q26*Summary!$F$9)/Summary!$F$10) | S26: =IF(R26="","",RANK(R26,$R$6:$R$305)) | T26: =IF(S26="","",IF(S26<=Summary!$B$5,"Featured candidate",""))
A27: P023 | B27: Heltech | D27: GitHub | E27: AI | F27: Done | G27: Featured | H27: https://github.com/Rajkumar-Ai-Engineer/HelTech | I27: No | J27: Yes | K27: Yes | L27: A full-stack healthcare / technology platform featuring a dedicated backend API, modern interactive frontend, containerized deployment setup, and automated CI/CD workflows. | R27: =IF(COUNT(M27:Q27)<5,"",(M27*Summary!$F$5+N27*Summary!$F$6+O27*Summary!$F$7+P27*Summary!$F$8+Q27*Summary!$F$9)/Summary!$F$10) | S27: =IF(R27="","",RANK(R27,$R$6:$R$305)) | T27: =IF(S27="","",IF(S27<=Summary!$B$5,"Featured candidate",""))
A28: P024 | B28: CustomerChurnPrediction | D28: GitHub | E28: ML | F28: Done | G28: Standard | H28: https://github.com/Rajkumar-Ai-Engineer/Streamlit_cloud_test | I28: No | J28: Yes | K28: Yes | L28: Customer churn preddiction end -end -ml | R28: =IF(COUNT(M28:Q28)<5,"",(M28*Summary!$F$5+N28*Summary!$F$6+O28*Summary!$F$7+P28*Summary!$F$8+Q28*Summary!$F$9)/Summary!$F$10) | S28: =IF(R28="","",RANK(R28,$R$6:$R$305)) | T28: =IF(S28="","",IF(S28<=Summary!$B$5,"Featured candidate",""))
A29: P025 | B29: DVC | D29: GitHub | E29: ML | F29: Done | G29: Archive | H29: https://github.com/Rajkumar-Ai-Engineer/DVC | I29: No | J29: Yes | K29: Yes | L29: A machine learning project setup demonstrating data versioning, pipeline orchestration, and model tracking using Data Version Control along with Git. | R29: =IF(COUNT(M29:Q29)<5,"",(M29*Summary!$F$5+N29*Summary!$F$6+O29*Summary!$F$7+P29*Summary!$F$8+Q29*Summary!$F$9)/Summary!$F$10) | S29: =IF(R29="","",RANK(R29,$R$6:$R$305)) | T29: =IF(S29="","",IF(S29<=Summary!$B$5,"Featured candidate",""))
A30: P026 | B30: MLFlow | D30: GitHub | E30: ML | F30: Done | G30: Archive | H30: https://github.com/Rajkumar-Ai-Engineer/MLFLOW | I30: No | J30: Yes | K30: Yes | L30: A hands-on implementation of MLflow for machine learning experiment tracking, covering both local tracking workflows and remote artifact and metric logging with DagsHub. | R30: =IF(COUNT(M30:Q30)<5,"",(M30*Summary!$F$5+N30*Summary!$F$6+O30*Summary!$F$7+P30*Summary!$F$8+Q30*Summary!$F$9)/Summary!$F$10) | S30: =IF(R30="","",RANK(R30,$R$6:$R$305)) | T30: =IF(S30="","",IF(S30<=Summary!$B$5,"Featured candidate",""))
... A37: P033 | B37: unsupervised learning and clustering analysis | D37: GitHub | E37: ML | F37: Done | G37: Archive | H37: https://github.com/Rajkumar-Ai-Engineer/MachineLearning-UnsupervisedLearning-clusters | I37: No | J37: Yes | K37: Yes | L37: a practical repository demonstrating unsupervised machine learning techniques, dimensionality reduction, and clustering algorithms applied to customer segmentation using the mall customers dataset. | R37: =IF(COUNT(M37:Q37)<5,"",(M37*Summary!$F$5+N37*Summary!$F$6+O37*Summary!$F$7+P37*Summary!$F$8+Q37*Summary!$F$9)/Summary!$F$10) | S37: =IF(R37="","",RANK(R37,$R$6:$R$305)) | T37: =IF(S37="","",IF(S37<=Summary!$B$5,"Featured candidate",""))
A38: P034 | B38: Resume Intelligence and Parser Pipeline | D38: GitHub | F38: Done | G38: Archive | H38: https://github.com/Rajkumar-Ai-Engineer/Resume-Intelligence-and-Parser-Pipeline | J38: Yes | K38: Yes | L38: An automated resume evaluation and text extraction pipeline designed to ingest candidate resumes, process structured details, and evaluate profiles using Python scripts and language model integrations. | R38: =IF(COUNT(M38:Q38)<5,"",(M38*Summary!$F$5+N38*Summary!$F$6+O38*Summary!$F$7+P38*Summary!$F$8+Q38*Summary!$F$9)/Summary!$F$10) | S38: =IF(R38="","",RANK(R38,$R$6:$R$305)) | T38: =IF(S38="","",IF(S38<=Summary!$B$5,"Featured candidate",""))
A39: P035 | D39: GitHub | F39: Done | J39: Yes | K39: Yes | R39: =IF(COUNT(M39:Q39)<5,"",(M39*Summary!$F$5+N39*Summary!$F$6+O39*Summary!$F$7+P39*Summary!$F$8+Q39*Summary!$F$9)/Summary!$F$10) | S39: =IF(R39="","",RANK(R39,$R$6:$R$305)) | T39: =IF(S39="","",IF(S39<=Summary!$B$5,"Featured candidate",""))
A40: P036 | D40: GitHub | F40: Done | K40: Yes | R40: =IF(COUNT(M40:Q40)<5,"",(M40*Summary!$F$5+N40*Summary!$F$6+O40*Summary!$F$7+P40*Summary!$F$8+Q40*Summary!$F$9)/Summary!$F$10) | S40: =IF(R40="","",RANK(R40,$R$6:$R$305)) | T40: =IF(S40="","",IF(S40<=Summary!$B$5,"Featured candidate",""))
A41: P037 | F41: Done | K41: Yes | R41: =IF(COUNT(M41:Q41)<5,"",(M41*Summary!$F$5+N41*Summary!$F$6+O41*Summary!$F$7+P41*Summary!$F$8+Q41*Summary!$F$9)/Summary!$F$10) | S41: =IF(R41="","",RANK(R41,$R$6:$R$305)) | T41: =IF(S41="","",IF(S41<=Summary!$B$5,"Featured candidate",""))
A42: P038 | R42: =IF(COUNT(M42:Q42)<5,"",(M42*Summary!$F$5+N42*Summary!$F$6+O42*Summary!$F$7+P42*Summary!$F$8+Q42*Summary!$F$9)/Summary!$F$10) | S42: =IF(R42="","",RANK(R42,$R$6:$R$305)) | T42: =IF(S42="","",IF(S42<=Summary!$B$5,"Featured candidate",""))
A43: P039 | R43: =IF(COUNT(M43:Q43)<5,"",(M43*Summary!$F$5+N43*Summary!$F$6+O43*Summary!$F$7+P43*Summary!$F$8+Q43*Summary!$F$9)/Summary!$F$10) | S43: =IF(R43="","",RANK(R43,$R$6:$R$305)) | T43: =IF(S43="","",IF(S43<=Summary!$B$5,"Featured candidate",""))
A44: P040 | R44: =IF(COUNT(M44:Q44)<5,"",(M44*Summary!$F$5+N44*Summary!$F$6+O44*Summary!$F$7+P44*Summary!$F$8+Q44*Summary!$F$9)/Summary!$F$10) | S44: =IF(R44="","",RANK(R44,$R$6:$R$305)) | T44: =IF(S44="","",IF(S44<=Summary!$B$5,"Featured candidate",""))
A45: P041 | R45: =IF(COUNT(M45:Q45)<5,"",(M45*Summary!$F$5+N45*Summary!$F$6+O45*Summary!$F$7+P45*Summary!$F$8+Q45*Summary!$F$9)/Summary!$F$10) | S45: =IF(R45="","",RANK(R45,$R$6:$R$305)) | T45: =IF(S45="","",IF(S45<=Summary!$B$5,"Featured candidate",""))
A46: P042 | R46: =IF(COUNT(M46:Q46)<5,"",(M46*Summary!$F$5+N46*Summary!$F$6+O46*Summary!$F$7+P46*Summary!$F$8+Q46*Summary!$F$9)/Summary!$F$10) | S46: =IF(R46="","",RANK(R46,$R$6:$R$305)) | T46: =IF(S46="","",IF(S46<=Summary!$B$5,"Featured candidate",""))
A47: P043 | R47: =IF(COUNT(M47:Q47)<5,"",(M47*Summary!$F$5+N47*Summary!$F$6+O47*Summary!$F$7+P47*Summary!$F$8+Q47*Summary!$F$9)/Summary!$F$10) | S47: =IF(R47="","",RANK(R47,$R$6:$R$305)) | T47: =IF(S47="","",IF(S47<=Summary!$B$5,"Featured candidate",""))
...

Sheet Summary
A1: Inventory summary
A2: All numbers are formulas that read the Projects sheet (rows 6 to 305). Nothing to edit here.
A4: Total projects listed | B4: =COUNTA(Projects!$B$6:$B$305) -> 33 | E4: Scoring criterion | F4: Weight
A5: Goal for Featured tier | B5: 10 | C5: Assumption: 8 to 10 featured projects (editable) | E5: Complexity and depth | F5: 25
A6: Featured still needed | B6: =MAX(0,B5-COUNTIF(Projects!$G$6:$G$305,"Featured")) -> 6 | E6: Demo-ability | F6: 25
E7: Relevance to goals | F7: 20
A8: By technology | B8: Count | E8: Recency | F8: 15
A9: AI | B9: =COUNTIF(Projects!$E$6:$E$305,A9) -> 1 | E9: Docs readiness | F9: 15
A10: ML | B10: =COUNTIF(Projects!$E$6:$E$305,A10) -> 7 | E10: Total (any scale works) | F10: =SUM(F5:F9) -> 100
A11: DL | B11: =COUNTIF(Projects!$E$6:$E$305,A11) -> 3 | E11: Assumption: weights chosen with the user in the planning chat; editable.
A12: Computer Vision | B12: =COUNTIF(Projects!$E$6:$E$305,A12) -> 2
A13: NLP | B13: =COUNTIF(Projects!$E$6:$E$305,A13) -> 0
A14: Gen AI | B14: =COUNTIF(Projects!$E$6:$E$305,A14) -> 13
A15: Agentic AI | B15: =COUNTIF(Projects!$E$6:$E$305,A15) -> 4
A16: Web Development | B16: =COUNTIF(Projects!$E$6:$E$305,A16) -> 0
A17: Other | B17: =COUNTIF(Projects!$E$6:$E$305,A17) -> 0
A18: Total | B18: =SUM(B9:B17) -> 30
A20: By source | B20: Count
A21: Laptop | B21: =COUNTIF(Projects!$D$6:$D$305,A21) -> 0
A22: Colab | B22: =COUNTIF(Projects!$D$6:$D$305,A22) -> 0
A23: Pendrive | B23: =COUNTIF(Projects!$D$6:$D$305,A23) -> 0
A24: GitHub | B24: =COUNTIF(Projects!$D$6:$D$305,A24) -> 35
A25: LinkedIn | B25: =COUNTIF(Projects!$D$6:$D$305,A25) -> 0
A26: Kaggle | B26: =COUNTIF(Projects!$D$6:$D$305,A26) -> 0
A27: Mobile | B27: =COUNTIF(Projects!$D$6:$D$305,A27) -> 0
A28: Other | B28: =COUNTIF(Projects!$D$6:$D$305,A28) -> 0
A29: Total | B29: =SUM(B21:B28) -> 35
A31: By tier | B31: Count
A32: Featured | B32: =COUNTIF(Projects!$G$6:$G$305,A32) -> 4
A33: Standard | B33: =COUNTIF(Projects!$G$6:$G$305,A33) -> 16
A34: Archive | B34: =COUNTIF(Projects!$G$6:$G$305,A34) -> 13
A35: Total | B35: =SUM(B32:B34) -> 33
A37: By status | B37: Count
A38: Done | B38: =COUNTIF(Projects!$F$6:$F$305,A38) -> 36
A39: In progress | B39: =COUNTIF(Projects!$F$6:$F$305,A39) -> 0
A40: Idea | B40: =COUNTIF(Projects!$F$6:$F$305,A40) -> 0
A41: Total | B41: =SUM(B38:B40) -> 36
